"""
Unit tests for error handling and logging in cueman
"""
import logging
import traceback
import unittest
from unittest.mock import patch, MagicMock

class TestErrorHandling(unittest.TestCase):
    def test_job_not_found_exception_handling(self):
        with self.assertLogs('cueman', level='ERROR') as log:
            try:
                logging.getLogger('cueman').error('Job not found')
                raise Exception('Job not found')
            except Exception as e:
                self.assertIn('Job not found', str(e))
            self.assertTrue(any('Job not found' in message for message in log.output))

    def test_network_connectivity_failure(self):
        with self.assertLogs('cueman', level='ERROR') as log:
            try:
                logging.getLogger('cueman').error('Network unreachable')
                raise ConnectionError('Network unreachable')
            except ConnectionError as e:
                self.assertIn('Network unreachable', str(e))
            self.assertTrue(any('Network unreachable' in message for message in log.output))

    def test_permission_denied_scenario(self):
        with self.assertLogs('cueman', level='ERROR') as log:
            try:
                logging.getLogger('cueman').error('Permission denied')
                raise PermissionError('Permission denied')
            except PermissionError as e:
                self.assertIn('Permission denied', str(e))
            self.assertTrue(any('Permission denied' in message for message in log.output))

    def test_invalid_argument_combinations(self):
        with self.assertLogs('cueman', level='ERROR') as log:
            try:
                logging.getLogger('cueman').error('Invalid arguments')
                raise ValueError('Invalid arguments')
            except ValueError as e:
                self.assertIn('Invalid arguments', str(e))
            self.assertTrue(any('Invalid arguments' in message for message in log.output))

    def test_timeout_handling(self):
        with self.assertLogs('cueman', level='ERROR') as log:
            try:
                logging.getLogger('cueman').error('Operation timed out')
                raise TimeoutError('Operation timed out')
            except TimeoutError as e:
                self.assertIn('Operation timed out', str(e))
            self.assertTrue(any('Operation timed out' in message for message in log.output))

    def test_error_message_formatting(self):
        with self.assertLogs('cueman', level='ERROR') as log:
            try:
                logging.getLogger('cueman').error('Custom error occurred')
                raise Exception('Custom error occurred')
            except Exception as e:
                self.assertTrue('Custom error occurred' in str(e))
            self.assertTrue(any('Custom error occurred' in message for message in log.output))

    def test_logging_level_configuration(self):
        logger = logging.getLogger('cueman')
        logger.setLevel(logging.ERROR)
        with self.assertLogs('cueman', level='ERROR') as log:
            try:
                logger.error('Log level test')
                raise Exception('Log level test')
            except Exception:
                pass
            self.assertTrue(any('Log level test' in message for message in log.output))
        logger.setLevel(logging.DEBUG)
        with self.assertLogs('cueman', level='DEBUG') as log:
            try:
                logger.debug('Log level test')
                raise Exception('Log level test')
            except Exception:
                pass
            self.assertTrue(any('Log level test' in message for message in log.output))

    def test_exception_traceback_in_verbose_mode(self):
        logger = logging.getLogger('cueman')
        logger.setLevel(logging.DEBUG)
        try:
            logger.error('Traceback test')
            raise Exception('Traceback test')
        except Exception as e:
            tb = traceback.format_exc()
            self.assertIn('Traceback', tb)
            self.assertIn('Traceback test', tb)

    def test_unexpected_exception_handling(self):
        with self.assertLogs('cueman', level='ERROR') as log:
            try:
                logging.getLogger('cueman').error('Unexpected error')
                raise Exception('Unexpected error')
            except Exception as e:
                self.assertIn('Unexpected error', str(e))
            self.assertTrue(any('Unexpected error' in message for message in log.output))

if __name__ == '__main__':
    unittest.main()
